Workbook

Sheet Read Me
B2: Personal Finance Tracker — Account Balances 2026
B3: Rebuilt from the Notion databases (Accounts, Income, Expenses, Transfers) on 2026-08-09.
B5: What is in this file
B6: Monthly Flows — one row per account per month: income, expenses, transfers in, transfers out.
B7: These are the only hardcoded numbers in the workbook (shown in blue).
B8: Balances — end-of-month balance per account, built with formulas from Monthly Flows.
B9: Investment Flows — the same transfers split into capital you added vs. returns the market gave.
B10: Invested vs Returns — capital, cumulative return and value per investment account, plus the
B11: money-weighted return. Value is checked against the Balances sheet.
B12: Charts — net worth, every account, and capital vs. portfolio value.
B14: How a balance is calculated
B15: Balance(account, month) = Balance(account, previous month) + income - expenses
... B37: To add a month, add its rows to Monthly Flows and insert a column on Balances copying the pattern.

Sheet Monthly Flows
A1: Monthly Flows — source data (blue cells are inputs)
A2: One row per account per month. Only months with activity are listed. Source: Notion Income / Expenses / Transfer databases.
A4: Account | B4: Month | C4: Income (€) | D4: Expenses (€) | E4: Transfers In (€) | F4: Transfers Out (€) | G4: Net Change (€)
A5: Conta Bolsas | B5: 2026-03 | C5: 0 | D5: 0 | E5: 4 | F5: 4 | G5: =C5-D5+E5-F5
A6: Conta Corrente | B6: 2026-01 | C6: 330 | D6: 1863.43 | E6: 4114.7 | F6: 1786.16 | G6: =C6-D6+E6-F6
A7: Conta Corrente | B7: 2026-02 | C7: 6928.7 | D7: 2955.16 | E7: 2821.54 | F7: 1315.24 | G7: =C7-D7+E7-F7
A8: Conta Corrente | B8: 2026-03 | C8: 3402.11 | D8: 811.12 | E8: 4 | F8: 3207.48 | G8: =C8-D8+E8-F8
A9: Conta Corrente | B9: 2026-04 | C9: 5012.96 | D9: 552.79 | E9: 0.45 | F9: 2454.3 | G9: =C9-D9+E9-F9
A10: Conta Corrente | B10: 2026-05 | C10: 3499.29 | D10: 970.97 | E10: 28.46 | F10: 4775.9 | G10: =C10-D10+E10-F10
A11: Conta Corrente | B11: 2026-06 | C11: 3499.29 | D11: 940.35 | E11: 1011.87 | F11: 7742.35 | G11: =C11-D11+E11-F11
A12: Conta Corrente | B12: 2026-07 | C12: 2446.4 | D12: 954.4 | E12: 252.26 | F12: 2470.71 | G12: =C12-D12+E12-F12
A13: Conta Corrente | B13: 2026-08 | C13: 0 | D13: 895 | E13: 1850 | F13: 1751.3 | G13: =C13-D13+E13-F13
A14: Conta Poupança | B14: 2026-01 | C14: 0 | D14: 0 | E14: 5 | F14: 1600 | G14: =C14-D14+E14-F14
A15: Conta Poupança | B15: 2026-02 | C15: 0 | D15: 0 | E15: 5 | F15: 1010.24 | G15: =C15-D15+E15-F15
A16: Conta Poupança | B16: 2026-03 | C16: 0 | D16: 0 | E16: 5 | F16: 0 | G16: =C16-D16+E16-F16
... A75: Trading 212 Account | B75: 2026-07 | C75: 0 | D75: 0 | E75: 10 | F75: 100 | G75: =C75-D75+E75-F75
A76: Total | C76: =SUM(C5:C75) | D76: =SUM(D5:D75) | E76: =SUM(E5:E75) | F76: =SUM(F5:F75) | G76: =SUM(G5:G75)

Sheet Balances
A1: End-of-month balance by account
A2: Every value below is a formula: previous month + net change pulled from Monthly Flows. Nothing here is typed in.
D3: month key → | E3: 2026-01 | F3: 2026-02 | G3: 2026-03 | H3: 2026-04 | I3: 2026-05 | J3: 2026-06 | K3: 2026-07 | L3: 2026-08
A4: Account | B4: Type | C4: Bank | D4: Start (1 Jan 2026) | E4: Jan 2026 | F4: Feb 2026 | G4: Mar 2026 | H4: Apr 2026 | I4: May 2026 | J4: Jun 2026 | K4: Jul 2026 | L4: Aug 2026
A5: Cash Withdrawls | B5: Cash | C5: — | D5: 0 | E5: =D5+SUMIFS('Monthly Flows'!$G$5:$G$75,'Monthly Flows'!$A$5:$A$75,$A5,'Monthly Flows'!$B$5:$B$75,E$3) | F5: =E5+SUMIFS('Monthly Flows'!$G$5:$G$75,'Monthly Flows'!$A$5:$A$75,$A5,'Monthly Flows'!$B$5:$B$75,F$3) | G5: =F5+SUMIFS('Monthly Flows'!$G$5:$G$75,'Monthly Flows'!$A$5:$A$75,$A5,'Monthly Flows'!$B$5:$B$75,G$3) | H5: =G5+SUMIFS('Monthly Flows'!$G$5:$G$75,'Monthly Flows'!$A$5:$A$75,$A5,'Monthly Flows'!$B$5:$B$75,H$3) | I5: =H5+SUMIFS('Monthly Flows'!$G$5:$G$75,'Monthly Flows'!$A$5:$A$75,$A5,'Monthly Flows'!$B$5:$B$75,I$3) | J5: =I5+SUMIFS('Monthly Flows'!$G$5:$G$75,'Monthly Flows'!$A$5:$A$75,$A5,'Monthly Flows'!$B$5:$B$75,J$3) | K5: =J5+SUMIFS('Monthly Flows'!$G$5:$G$75,'Monthly Flows'!$A$5:$A$75,$A5,'Monthly Flows'!$B$5:$B$75,K$3) | L5: =K5+SUMIFS('Monthly Flows'!$G$5:$G$75,'Monthly Flows'!$A$5:$A$75,$A5,'Monthly Flows'!$B$5:$B$75,L$3)
A6: Certificados de Aforro CTT - Série E | B6: Investment | C6: CTT/Estado | D6: 534.73 | E6: =D6+SUMIFS('Monthly Flows'!$G$5:$G$75,'Monthly Flows'!$A$5:$A$75,$A6,'Monthly Flows'!$B$5:$B$75,E$3) | F6: =E6+SUMIFS('Monthly Flows'!$G$5:$G$75,'Monthly Flows'!$A$5:$A$75,$A6,'Monthly Flows'!$B$5:$B$75,F$3) | G6: =F6+SUMIFS('Monthly Flows'!$G$5:$G$75,'Monthly Flows'!$A$5:$A$75,$A6,'Monthly Flows'!$B$5:$B$75,G$3) | H6: =G6+SUMIFS('Monthly Flows'!$G$5:$G$75,'Monthly Flows'!$A$5:$A$75,$A6,'Monthly Flows'!$B$5:$B$75,H$3) | I6: =H6+SUMIFS('Monthly Flows'!$G$5:$G$75,'Monthly Flows'!$A$5:$A$75,$A6,'Monthly Flows'!$B$5:$B$75,I$3) | J6: =I6+SUMIFS('Monthly Flows'!$G$5:$G$75,'Monthly Flows'!$A$5:$A$75,$A6,'Monthly Flows'!$B$5:$B$75,J$3) | K6: =J6+SUMIFS('Monthly Flows'!$G$5:$G$75,'Monthly Flows'!$A$5:$A$75,$A6,'Monthly Flows'!$B$5:$B$75,K$3) | L6: =K6+SUMIFS('Monthly Flows'!$G$5:$G$75,'Monthly Flows'!$A$5:$A$75,$A6,'Monthly Flows'!$B$5:$B$75,L$3)
A7: Certificados de Aforro CTT - Série F | B7: Investment | C7: CTT/Estado | D7: 5512.73 | E7: =D7+SUMIFS('Monthly Flows'!$G$5:$G$75,'Monthly Flows'!$A$5:$A$75,$A7,'Monthly Flows'!$B$5:$B$75,E$3) | F7: =E7+SUMIFS('Monthly Flows'!$G$5:$G$75,'Monthly Flows'!$A$5:$A$75,$A7,'Monthly Flows'!$B$5:$B$75,F$3) | G7: =F7+SUMIFS('Monthly Flows'!$G$5:$G$75,'Monthly Flows'!$A$5:$A$75,$A7,'Monthly Flows'!$B$5:$B$75,G$3) | H7: =G7+SUMIFS('Monthly Flows'!$G$5:$G$75,'Monthly Flows'!$A$5:$A$75,$A7,'Monthly Flows'!$B$5:$B$75,H$3) | I7: =H7+SUMIFS('Monthly Flows'!$G$5:$G$75,'Monthly Flows'!$A$5:$A$75,$A7,'Monthly Flows'!$B$5:$B$75,I$3) | J7: =I7+SUMIFS('Monthly Flows'!$G$5:$G$75,'Monthly Flows'!$A$5:$A$75,$A7,'Monthly Flows'!$B$5:$B$75,J$3) | K7: =J7+SUMIFS('Monthly Flows'!$G$5:$G$75,'Monthly Flows'!$A$5:$A$75,$A7,'Monthly Flows'!$B$5:$B$75,K$3) | L7: =K7+SUMIFS('Monthly Flows'!$G$5:$G$75,'Monthly Flows'!$A$5:$A$75,$A7,'Monthly Flows'!$B$5:$B$75,L$3)
A8: Conta Bolsas | B8: Account | C8: Santander | D8: 0 | E8: =D8+SUMIFS('Monthly Flows'!$G$5:$G$75,'Monthly Flows'!$A$5:$A$75,$A8,'Monthly Flows'!$B$5:$B$75,E$3) | F8: =E8+SUMIFS('Monthly Flows'!$G$5:$G$75,'Monthly Flows'!$A$5:$A$75,$A8,'Monthly Flows'!$B$5:$B$75,F$3) | G8: =F8+SUMIFS('Monthly Flows'!$G$5:$G$75,'Monthly Flows'!$A$5:$A$75,$A8,'Monthly Flows'!$B$5:$B$75,G$3) | H8: =G8+SUMIFS('Monthly Flows'!$G$5:$G$75,'Monthly Flows'!$A$5:$A$75,$A8,'Monthly Flows'!$B$5:$B$75,H$3) | I8: =H8+SUMIFS('Monthly Flows'!$G$5:$G$75,'Monthly Flows'!$A$5:$A$75,$A8,'Monthly Flows'!$B$5:$B$75,I$3) | J8: =I8+SUMIFS('Monthly Flows'!$G$5:$G$75,'Monthly Flows'!$A$5:$A$75,$A8,'Monthly Flows'!$B$5:$B$75,J$3) | K8: =J8+SUMIFS('Monthly Flows'!$G$5:$G$75,'Monthly Flows'!$A$5:$A$75,$A8,'Monthly Flows'!$B$5:$B$75,K$3) | L8: =K8+SUMIFS('Monthly Flows'!$G$5:$G$75,'Monthly Flows'!$A$5:$A$75,$A8,'Monthly Flows'!$B$5:$B$75,L$3)
A9: Conta Corrente | B9: Account | C9: Santander | D9: 344.63 | E9: =D9+SUMIFS('Monthly Flows'!$G$5:$G$75,'Monthly Flows'!$A$5:$A$75,$A9,'Monthly Flows'!$B$5:$B$75,E$3) | F9: =E9+SUMIFS('Monthly Flows'!$G$5:$G$75,'Monthly Flows'!$A$5:$A$75,$A9,'Monthly Flows'!$B$5:$B$75,F$3) | G9: =F9+SUMIFS('Monthly Flows'!$G$5:$G$75,'Monthly Flows'!$A$5:$A$75,$A9,'Monthly Flows'!$B$5:$B$75,G$3) | H9: =G9+SUMIFS('Monthly Flows'!$G$5:$G$75,'Monthly Flows'!$A$5:$A$75,$A9,'Monthly Flows'!$B$5:$B$75,H$3) | I9: =H9+SUMIFS('Monthly Flows'!$G$5:$G$75,'Monthly Flows'!$A$5:$A$75,$A9,'Monthly Flows'!$B$5:$B$75,I$3) | J9: =I9+SUMIFS('Monthly Flows'!$G$5:$G$75,'Monthly Flows'!$A$5:$A$75,$A9,'Monthly Flows'!$B$5:$B$75,J$3) | K9: =J9+SUMIFS('Monthly Flows'!$G$5:$G$75,'Monthly Flows'!$A$5:$A$75,$A9,'Monthly Flows'!$B$5:$B$75,K$3) | L9: =K9+SUMIFS('Monthly Flows'!$G$5:$G$75,'Monthly Flows'!$A$5:$A$75,$A9,'Monthly Flows'!$B$5:$B$75,L$3)
A10: Conta Poupança | B10: Account | C10: Santander | D10: 2600.31 | E10: =D10+SUMIFS('Monthly Flows'!$G$5:$G$75,'Monthly Flows'!$A$5:$A$75,$A10,'Monthly Flows'!$B$5:$B$75,E$3) | F10: =E10+SUMIFS('Monthly Flows'!$G$5:$G$75,'Monthly Flows'!$A$5:$A$75,$A10,'Monthly Flows'!$B$5:$B$75,F$3) | G10: =F10+SUMIFS('Monthly Flows'!$G$5:$G$75,'Monthly Flows'!$A$5:$A$75,$A10,'Monthly Flows'!$B$5:$B$75,G$3) | H10: =G10+SUMIFS('Monthly Flows'!$G$5:$G$75,'Monthly Flows'!$A$5:$A$75,$A10,'Monthly Flows'!$B$5:$B$75,H$3) | I10: =H10+SUMIFS('Monthly Flows'!$G$5:$G$75,'Monthly Flows'!$A$5:$A$75,$A10,'Monthly Flows'!$B$5:$B$75,I$3) | J10: =I10+SUMIFS('Monthly Flows'!$G$5:$G$75,'Monthly Flows'!$A$5:$A$75,$A10,'Monthly Flows'!$B$5:$B$75,J$3) | K10: =J10+SUMIFS('Monthly Flows'!$G$5:$G$75,'Monthly Flows'!$A$5:$A$75,$A10,'Monthly Flows'!$B$5:$B$75,K$3) | L10: =K10+SUMIFS('Monthly Flows'!$G$5:$G$75,'Monthly Flows'!$A$5:$A$75,$A10,'Monthly Flows'!$B$5:$B$75,L$3)
A11: PayPal | B11: Account | C11: PayPal | D11: 0 | E11: =D11+SUMIFS('Monthly Flows'!$G$5:$G$75,'Monthly Flows'!$A$5:$A$75,$A11,'Monthly Flows'!$B$5:$B$75,E$3) | F11: =E11+SUMIFS('Monthly Flows'!$G$5:$G$75,'Monthly Flows'!$A$5:$A$75,$A11,'Monthly Flows'!$B$5:$B$75,F$3) | G11: =F11+SUMIFS('Monthly Flows'!$G$5:$G$75,'Monthly Flows'!$A$5:$A$75,$A11,'Monthly Flows'!$B$5:$B$75,G$3) | H11: =G11+SUMIFS('Monthly Flows'!$G$5:$G$75,'Monthly Flows'!$A$5:$A$75,$A11,'Monthly Flows'!$B$5:$B$75,H$3) | I11: =H11+SUMIFS('Monthly Flows'!$G$5:$G$75,'Monthly Flows'!$A$5:$A$75,$A11,'Monthly Flows'!$B$5:$B$75,I$3) | J11: =I11+SUMIFS('Monthly Flows'!$G$5:$G$75,'Monthly Flows'!$A$5:$A$75,$A11,'Monthly Flows'!$B$5:$B$75,J$3) | K11: =J11+SUMIFS('Monthly Flows'!$G$5:$G$75,'Monthly Flows'!$A$5:$A$75,$A11,'Monthly Flows'!$B$5:$B$75,K$3) | L11: =K11+SUMIFS('Monthly Flows'!$G$5:$G$75,'Monthly Flows'!$A$5:$A$75,$A11,'Monthly Flows'!$B$5:$B$75,L$3)
A12: Revolut | B12: Account | C12: Revolut | D12: 0 | E12: =D12+SUMIFS('Monthly Flows'!$G$5:$G$75,'Monthly Flows'!$A$5:$A$75,$A12,'Monthly Flows'!$B$5:$B$75,E$3) | F12: =E12+SUMIFS('Monthly Flows'!$G$5:$G$75,'Monthly Flows'!$A$5:$A$75,$A12,'Monthly Flows'!$B$5:$B$75,F$3) | G12: =F12+SUMIFS('Monthly Flows'!$G$5:$G$75,'Monthly Flows'!$A$5:$A$75,$A12,'Monthly Flows'!$B$5:$B$75,G$3) | H12: =G12+SUMIFS('Monthly Flows'!$G$5:$G$75,'Monthly Flows'!$A$5:$A$75,$A12,'Monthly Flows'!$B$5:$B$75,H$3) | I12: =H12+SUMIFS('Monthly Flows'!$G$5:$G$75,'Monthly Flows'!$A$5:$A$75,$A12,'Monthly Flows'!$B$5:$B$75,I$3) | J12: =I12+SUMIFS('Monthly Flows'!$G$5:$G$75,'Monthly Flows'!$A$5:$A$75,$A12,'Monthly Flows'!$B$5:$B$75,J$3) | K12: =J12+SUMIFS('Monthly Flows'!$G$5:$G$75,'Monthly Flows'!$A$5:$A$75,$A12,'Monthly Flows'!$B$5:$B$75,K$3) | L12: =K12+SUMIFS('Monthly Flows'!$G$5:$G$75,'Monthly Flows'!$A$5:$A$75,$A12,'Monthly Flows'!$B$5:$B$75,L$3)
A13: Revolut - Fundo Emergência | B13: Investment | C13: Revolut | D13: 0 | E13: =D13+SUMIFS('Monthly Flows'!$G$5:$G$75,'Monthly Flows'!$A$5:$A$75,$A13,'Monthly Flows'!$B$5:$B$75,E$3) | F13: =E13+SUMIFS('Monthly Flows'!$G$5:$G$75,'Monthly Flows'!$A$5:$A$75,$A13,'Monthly Flows'!$B$5:$B$75,F$3) | G13: =F13+SUMIFS('Monthly Flows'!$G$5:$G$75,'Monthly Flows'!$A$5:$A$75,$A13,'Monthly Flows'!$B$5:$B$75,G$3) | H13: =G13+SUMIFS('Monthly Flows'!$G$5:$G$75,'Monthly Flows'!$A$5:$A$75,$A13,'Monthly Flows'!$B$5:$B$75,H$3) | I13: =H13+SUMIFS('Monthly Flows'!$G$5:$G$75,'Monthly Flows'!$A$5:$A$75,$A13,'Monthly Flows'!$B$5:$B$75,I$3) | J13: =I13+SUMIFS('Monthly Flows'!$G$5:$G$75,'Monthly Flows'!$A$5:$A$75,$A13,'Monthly Flows'!$B$5:$B$75,J$3) | K13: =J13+SUMIFS('Monthly Flows'!$G$5:$G$75,'Monthly Flows'!$A$5:$A$75,$A13,'Monthly Flows'!$B$5:$B$75,K$3) | L13: =K13+SUMIFS('Monthly Flows'!$G$5:$G$75,'Monthly Flows'!$A$5:$A$75,$A13,'Monthly Flows'!$B$5:$B$75,L$3)
A14: Revolut - Wealth Build | B14: Investment | C14: Revolut | D14: 0 | E14: =D14+SUMIFS('Monthly Flows'!$G$5:$G$75,'Monthly Flows'!$A$5:$A$75,$A14,'Monthly Flows'!$B$5:$B$75,E$3) | F14: =E14+SUMIFS('Monthly Flows'!$G$5:$G$75,'Monthly Flows'!$A$5:$A$75,$A14,'Monthly Flows'!$B$5:$B$75,F$3) | G14: =F14+SUMIFS('Monthly Flows'!$G$5:$G$75,'Monthly Flows'!$A$5:$A$75,$A14,'Monthly Flows'!$B$5:$B$75,G$3) | H14: =G14+SUMIFS('Monthly Flows'!$G$5:$G$75,'Monthly Flows'!$A$5:$A$75,$A14,'Monthly Flows'!$B$5:$B$75,H$3) | I14: =H14+SUMIFS('Monthly Flows'!$G$5:$G$75,'Monthly Flows'!$A$5:$A$75,$A14,'Monthly Flows'!$B$5:$B$75,I$3) | J14: =I14+SUMIFS('Monthly Flows'!$G$5:$G$75,'Monthly Flows'!$A$5:$A$75,$A14,'Monthly Flows'!$B$5:$B$75,J$3) | K14: =J14+SUMIFS('Monthly Flows'!$G$5:$G$75,'Monthly Flows'!$A$5:$A$75,$A14,'Monthly Flows'!$B$5:$B$75,K$3) | L14: =K14+SUMIFS('Monthly Flows'!$G$5:$G$75,'Monthly Flows'!$A$5:$A$75,$A14,'Monthly Flows'!$B$5:$B$75,L$3)
A15: Robinhood | B15: Investment | C15: Robinhood | D15: 0 | E15: =D15+SUMIFS('Monthly Flows'!$G$5:$G$75,'Monthly Flows'!$A$5:$A$75,$A15,'Monthly Flows'!$B$5:$B$75,E$3) | F15: =E15+SUMIFS('Monthly Flows'!$G$5:$G$75,'Monthly Flows'!$A$5:$A$75,$A15,'Monthly Flows'!$B$5:$B$75,F$3) | G15: =F15+SUMIFS('Monthly Flows'!$G$5:$G$75,'Monthly Flows'!$A$5:$A$75,$A15,'Monthly Flows'!$B$5:$B$75,G$3) | H15: =G15+SUMIFS('Monthly Flows'!$G$5:$G$75,'Monthly Flows'!$A$5:$A$75,$A15,'Monthly Flows'!$B$5:$B$75,H$3) | I15: =H15+SUMIFS('Monthly Flows'!$G$5:$G$75,'Monthly Flows'!$A$5:$A$75,$A15,'Monthly Flows'!$B$5:$B$75,I$3) | J15: =I15+SUMIFS('Monthly Flows'!$G$5:$G$75,'Monthly Flows'!$A$5:$A$75,$A15,'Monthly Flows'!$B$5:$B$75,J$3) | K15: =J15+SUMIFS('Monthly Flows'!$G$5:$G$75,'Monthly Flows'!$A$5:$A$75,$A15,'Monthly Flows'!$B$5:$B$75,K$3) | L15: =K15+SUMIFS('Monthly Flows'!$G$5:$G$75,'Monthly Flows'!$A$5:$A$75,$A15,'Monthly Flows'!$B$5:$B$75,L$3)
A16: Trade Republic Account | B16: Account | C16: Trade Republic | D16: 340.94 | E16: =D16+SUMIFS('Monthly Flows'!$G$5:$G$75,'Monthly Flows'!$A$5:$A$75,$A16,'Monthly Flows'!$B$5:$B$75,E$3) | F16: =E16+SUMIFS('Monthly Flows'!$G$5:$G$75,'Monthly Flows'!$A$5:$A$75,$A16,'Monthly Flows'!$B$5:$B$75,F$3) | G16: =F16+SUMIFS('Monthly Flows'!$G$5:$G$75,'Monthly Flows'!$A$5:$A$75,$A16,'Monthly Flows'!$B$5:$B$75,G$3) | H16: =G16+SUMIFS('Monthly Flows'!$G$5:$G$75,'Monthly Flows'!$A$5:$A$75,$A16,'Monthly Flows'!$B$5:$B$75,H$3) | I16: =H16+SUMIFS('Monthly Flows'!$G$5:$G$75,'Monthly Flows'!$A$5:$A$75,$A16,'Monthly Flows'!$B$5:$B$75,I$3) | J16: =I16+SUMIFS('Monthly Flows'!$G$5:$G$75,'Monthly Flows'!$A$5:$A$75,$A16,'Monthly Flows'!$B$5:$B$75,J$3) | K16: =J16+SUMIFS('Monthly Flows'!$G$5:$G$75,'Monthly Flows'!$A$5:$A$75,$A16,'Monthly Flows'!$B$5:$B$75,K$3) | L16: =K16+SUMIFS('Monthly Flows'!$G$5:$G$75,'Monthly Flows'!$A$5:$A$75,$A16,'Monthly Flows'!$B$5:$B$75,L$3)
... A19: Trading 212 Account | B19: Investment | C19: Trading 212 | D19: 0 | E19: =D19+SUMIFS('Monthly Flows'!$G$5:$G$75,'Monthly Flows'!$A$5:$A$75,$A19,'Monthly Flows'!$B$5:$B$75,E$3) | F19: =E19+SUMIFS('Monthly Flows'!$G$5:$G$75,'Monthly Flows'!$A$5:$A$75,$A19,'Monthly Flows'!$B$5:$B$75,F$3) | G19: =F19+SUMIFS('Monthly Flows'!$G$5:$G$75,'Monthly Flows'!$A$5:$A$75,$A19,'Monthly Flows'!$B$5:$B$75,G$3) | H19: =G19+SUMIFS('Monthly Flows'!$G$5:$G$75,'Monthly Flows'!$A$5:$A$75,$A19,'Monthly Flows'!$B$5:$B$75,H$3) | I19: =H19+SUMIFS('Monthly Flows'!$G$5:$G$75,'Monthly Flows'!$A$5:$A$75,$A19,'Monthly Flows'!$B$5:$B$75,I$3) | J19: =I19+SUMIFS('Monthly Flows'!$G$5:$G$75,'Monthly Flows'!$A$5:$A$75,$A19,'Monthly Flows'!$B$5:$B$75,J$3) | K19: =J19+SUMIFS('Monthly Flows'!$G$5:$G$75,'Monthly Flows'!$A$5:$A$75,$A19,'Monthly Flows'!$B$5:$B$75,K$3) | L19: =K19+SUMIFS('Monthly Flows'!$G$5:$G$75,'Monthly Flows'!$A$5:$A$75,$A19,'Monthly Flows'!$B$5:$B$75,L$3)
A20: TOTAL — net worth | D20: =SUM(D5:D19) | E20: =SUM(E5:E19) | F20: =SUM(F5:F19) | G20: =SUM(G5:G19) | H20: =SUM(H5:H19) | I20: =SUM(I5:I19) | J20: =SUM(J5:J19) | K20: =SUM(K5:K19) | L20: =SUM(L5:L19)
A22: Change since 1 Jan 2026 | L22: =L20-D20
A24: Starting balances come from the 'Starting Balance (as of January 1st 2026)' field in the Notion Accounts database. August 2026 is partial (last transaction 5 Aug 2026). See Read Me for all assumptions.

Sheet Investment Flows
A1: Investment Flows — capital vs. return, split at source (blue cells are inputs)
A2: A transfer between two of your own accounts is capital moving. A one-sided transfer on an investment account (no From or no To) is a gain or a loss — in Notion these are the Portfolio Delta / CTT Aforro Delta / fund delta rows. Net = in minus out for that month.
A4: Investment account | B4: Month | C4: Net Capital In (€) | D4: Net Return (€)
A5: Certificados de Aforro CTT - Série E | B5: 2026-02 | C5: 0 | D5: 3.37
A6: Certificados de Aforro CTT - Série E | B6: 2026-05 | C6: 0 | D6: 3.44
A7: Certificados de Aforro CTT - Série F | B7: 2026-02 | C7: 0 | D7: 20.9
A8: Certificados de Aforro CTT - Série F | B8: 2026-04 | C8: 0 | D8: 1.57
A9: Certificados de Aforro CTT - Série F | B9: 2026-05 | C9: 0 | D9: 21.3
A10: Certificados de Aforro CTT - Série F | B10: 2026-08 | C10: -1851.19 | D10: 0
A11: Revolut - Fundo Emergência | B11: 2026-06 | C11: 405 | D11: 0
A12: Revolut - Fundo Emergência | B12: 2026-07 | C12: 41 | D12: 0.82
A13: Revolut - Fundo Emergência | B13: 2026-08 | C13: -396 | D13: 0
A14: Revolut - Wealth Build | B14: 2026-06 | C14: 250 | D14: 0
A15: Revolut - Wealth Build | B15: 2026-07 | C15: 225 | D15: 0.54
A16: Revolut - Wealth Build | B16: 2026-08 | C16: -35 | D16: 0
... A33: Trading 212 Account | B33: 2026-07 | C33: -90 | D33: 0
A34: Total | C34: =SUM(C5:C33) | D34: =SUM(D5:D33)

Sheet Invested vs Returns
A1: Invested capital vs. returns
A2: Three blocks: capital you put in, cumulative return, and value (capital + return). Value must equal the same account on the Balances sheet — row 3 of each Value row checks it.
A4: Capital invested | E4: 2026-01 | F4: 2026-02 | G4: 2026-03 | H4: 2026-04 | I4: 2026-05 | J4: 2026-06 | K4: 2026-07 | L4: 2026-08
A5: Account | D5: 1 Jan | E5: Jan 2026 | F5: Feb 2026 | G5: Mar 2026 | H5: Apr 2026 | I5: May 2026 | J5: Jun 2026 | K5: Jul 2026 | L5: Aug 2026
A6: Certificados de Aforro CTT - Série E | D6: 534.73 | E6: =D6+SUMIFS('Investment Flows'!$C$5:$C$33,'Investment Flows'!$A$5:$A$33,$A6,'Investment Flows'!$B$5:$B$33,E$4) | F6: =E6+SUMIFS('Investment Flows'!$C$5:$C$33,'Investment Flows'!$A$5:$A$33,$A6,'Investment Flows'!$B$5:$B$33,F$4) | G6: =F6+SUMIFS('Investment Flows'!$C$5:$C$33,'Investment Flows'!$A$5:$A$33,$A6,'Investment Flows'!$B$5:$B$33,G$4) | H6: =G6+SUMIFS('Investment Flows'!$C$5:$C$33,'Investment Flows'!$A$5:$A$33,$A6,'Investment Flows'!$B$5:$B$33,H$4) | I6: =H6+SUMIFS('Investment Flows'!$C$5:$C$33,'Investment Flows'!$A$5:$A$33,$A6,'Investment Flows'!$B$5:$B$33,I$4) | J6: =I6+SUMIFS('Investment Flows'!$C$5:$C$33,'Investment Flows'!$A$5:$A$33,$A6,'Investment Flows'!$B$5:$B$33,J$4) | K6: =J6+SUMIFS('Investment Flows'!$C$5:$C$33,'Investment Flows'!$A$5:$A$33,$A6,'Investment Flows'!$B$5:$B$33,K$4) | L6: =K6+SUMIFS('Investment Flows'!$C$5:$C$33,'Investment Flows'!$A$5:$A$33,$A6,'Investment Flows'!$B$5:$B$33,L$4)
A7: Certificados de Aforro CTT - Série F | D7: 5512.73 | E7: =D7+SUMIFS('Investment Flows'!$C$5:$C$33,'Investment Flows'!$A$5:$A$33,$A7,'Investment Flows'!$B$5:$B$33,E$4) | F7: =E7+SUMIFS('Investment Flows'!$C$5:$C$33,'Investment Flows'!$A$5:$A$33,$A7,'Investment Flows'!$B$5:$B$33,F$4) | G7: =F7+SUMIFS('Investment Flows'!$C$5:$C$33,'Investment Flows'!$A$5:$A$33,$A7,'Investment Flows'!$B$5:$B$33,G$4) | H7: =G7+SUMIFS('Investment Flows'!$C$5:$C$33,'Investment Flows'!$A$5:$A$33,$A7,'Investment Flows'!$B$5:$B$33,H$4) | I7: =H7+SUMIFS('Investment Flows'!$C$5:$C$33,'Investment Flows'!$A$5:$A$33,$A7,'Investment Flows'!$B$5:$B$33,I$4) | J7: =I7+SUMIFS('Investment Flows'!$C$5:$C$33,'Investment Flows'!$A$5:$A$33,$A7,'Investment Flows'!$B$5:$B$33,J$4) | K7: =J7+SUMIFS('Investment Flows'!$C$5:$C$33,'Investment Flows'!$A$5:$A$33,$A7,'Investment Flows'!$B$5:$B$33,K$4) | L7: =K7+SUMIFS('Investment Flows'!$C$5:$C$33,'Investment Flows'!$A$5:$A$33,$A7,'Investment Flows'!$B$5:$B$33,L$4)
A8: Revolut - Fundo Emergência | D8: 0 | E8: =D8+SUMIFS('Investment Flows'!$C$5:$C$33,'Investment Flows'!$A$5:$A$33,$A8,'Investment Flows'!$B$5:$B$33,E$4) | F8: =E8+SUMIFS('Investment Flows'!$C$5:$C$33,'Investment Flows'!$A$5:$A$33,$A8,'Investment Flows'!$B$5:$B$33,F$4) | G8: =F8+SUMIFS('Investment Flows'!$C$5:$C$33,'Investment Flows'!$A$5:$A$33,$A8,'Investment Flows'!$B$5:$B$33,G$4) | H8: =G8+SUMIFS('Investment Flows'!$C$5:$C$33,'Investment Flows'!$A$5:$A$33,$A8,'Investment Flows'!$B$5:$B$33,H$4) | I8: =H8+SUMIFS('Investment Flows'!$C$5:$C$33,'Investment Flows'!$A$5:$A$33,$A8,'Investment Flows'!$B$5:$B$33,I$4) | J8: =I8+SUMIFS('Investment Flows'!$C$5:$C$33,'Investment Flows'!$A$5:$A$33,$A8,'Investment Flows'!$B$5:$B$33,J$4) | K8: =J8+SUMIFS('Investment Flows'!$C$5:$C$33,'Investment Flows'!$A$5:$A$33,$A8,'Investment Flows'!$B$5:$B$33,K$4) | L8: =K8+SUMIFS('Investment Flows'!$C$5:$C$33,'Investment Flows'!$A$5:$A$33,$A8,'Investment Flows'!$B$5:$B$33,L$4)
A9: Revolut - Wealth Build | D9: 0 | E9: =D9+SUMIFS('Investment Flows'!$C$5:$C$33,'Investment Flows'!$A$5:$A$33,$A9,'Investment Flows'!$B$5:$B$33,E$4) | F9: =E9+SUMIFS('Investment Flows'!$C$5:$C$33,'Investment Flows'!$A$5:$A$33,$A9,'Investment Flows'!$B$5:$B$33,F$4) | G9: =F9+SUMIFS('Investment Flows'!$C$5:$C$33,'Investment Flows'!$A$5:$A$33,$A9,'Investment Flows'!$B$5:$B$33,G$4) | H9: =G9+SUMIFS('Investment Flows'!$C$5:$C$33,'Investment Flows'!$A$5:$A$33,$A9,'Investment Flows'!$B$5:$B$33,H$4) | I9: =H9+SUMIFS('Investment Flows'!$C$5:$C$33,'Investment Flows'!$A$5:$A$33,$A9,'Investment Flows'!$B$5:$B$33,I$4) | J9: =I9+SUMIFS('Investment Flows'!$C$5:$C$33,'Investment Flows'!$A$5:$A$33,$A9,'Investment Flows'!$B$5:$B$33,J$4) | K9: =J9+SUMIFS('Investment Flows'!$C$5:$C$33,'Investment Flows'!$A$5:$A$33,$A9,'Investment Flows'!$B$5:$B$33,K$4) | L9: =K9+SUMIFS('Investment Flows'!$C$5:$C$33,'Investment Flows'!$A$5:$A$33,$A9,'Investment Flows'!$B$5:$B$33,L$4)
A10: Robinhood | D10: 0 | E10: =D10+SUMIFS('Investment Flows'!$C$5:$C$33,'Investment Flows'!$A$5:$A$33,$A10,'Investment Flows'!$B$5:$B$33,E$4) | F10: =E10+SUMIFS('Investment Flows'!$C$5:$C$33,'Investment Flows'!$A$5:$A$33,$A10,'Investment Flows'!$B$5:$B$33,F$4) | G10: =F10+SUMIFS('Investment Flows'!$C$5:$C$33,'Investment Flows'!$A$5:$A$33,$A10,'Investment Flows'!$B$5:$B$33,G$4) | H10: =G10+SUMIFS('Investment Flows'!$C$5:$C$33,'Investment Flows'!$A$5:$A$33,$A10,'Investment Flows'!$B$5:$B$33,H$4) | I10: =H10+SUMIFS('Investment Flows'!$C$5:$C$33,'Investment Flows'!$A$5:$A$33,$A10,'Investment Flows'!$B$5:$B$33,I$4) | J10: =I10+SUMIFS('Investment Flows'!$C$5:$C$33,'Investment Flows'!$A$5:$A$33,$A10,'Investment Flows'!$B$5:$B$33,J$4) | K10: =J10+SUMIFS('Investment Flows'!$C$5:$C$33,'Investment Flows'!$A$5:$A$33,$A10,'Investment Flows'!$B$5:$B$33,K$4) | L10: =K10+SUMIFS('Investment Flows'!$C$5:$C$33,'Investment Flows'!$A$5:$A$33,$A10,'Investment Flows'!$B$5:$B$33,L$4)
A11: Trade Republic Inv. - Brokerage | D11: 7687.87 | E11: =D11+SUMIFS('Investment Flows'!$C$5:$C$33,'Investment Flows'!$A$5:$A$33,$A11,'Investment Flows'!$B$5:$B$33,E$4) | F11: =E11+SUMIFS('Investment Flows'!$C$5:$C$33,'Investment Flows'!$A$5:$A$33,$A11,'Investment Flows'!$B$5:$B$33,F$4) | G11: =F11+SUMIFS('Investment Flows'!$C$5:$C$33,'Investment Flows'!$A$5:$A$33,$A11,'Investment Flows'!$B$5:$B$33,G$4) | H11: =G11+SUMIFS('Investment Flows'!$C$5:$C$33,'Investment Flows'!$A$5:$A$33,$A11,'Investment Flows'!$B$5:$B$33,H$4) | I11: =H11+SUMIFS('Investment Flows'!$C$5:$C$33,'Investment Flows'!$A$5:$A$33,$A11,'Investment Flows'!$B$5:$B$33,I$4) | J11: =I11+SUMIFS('Investment Flows'!$C$5:$C$33,'Investment Flows'!$A$5:$A$33,$A11,'Investment Flows'!$B$5:$B$33,J$4) | K11: =J11+SUMIFS('Investment Flows'!$C$5:$C$33,'Investment Flows'!$A$5:$A$33,$A11,'Investment Flows'!$B$5:$B$33,K$4) | L11: =K11+SUMIFS('Investment Flows'!$C$5:$C$33,'Investment Flows'!$A$5:$A$33,$A11,'Investment Flows'!$B$5:$B$33,L$4)
A12: Trade Republic Inv. - Crypto | D12: 0 | E12: =D12+SUMIFS('Investment Flows'!$C$5:$C$33,'Investment Flows'!$A$5:$A$33,$A12,'Investment Flows'!$B$5:$B$33,E$4) | F12: =E12+SUMIFS('Investment Flows'!$C$5:$C$33,'Investment Flows'!$A$5:$A$33,$A12,'Investment Flows'!$B$5:$B$33,F$4) | G12: =F12+SUMIFS('Investment Flows'!$C$5:$C$33,'Investment Flows'!$A$5:$A$33,$A12,'Investment Flows'!$B$5:$B$33,G$4) | H12: =G12+SUMIFS('Investment Flows'!$C$5:$C$33,'Investment Flows'!$A$5:$A$33,$A12,'Investment Flows'!$B$5:$B$33,H$4) | I12: =H12+SUMIFS('Investment Flows'!$C$5:$C$33,'Investment Flows'!$A$5:$A$33,$A12,'Investment Flows'!$B$5:$B$33,I$4) | J12: =I12+SUMIFS('Investment Flows'!$C$5:$C$33,'Investment Flows'!$A$5:$A$33,$A12,'Investment Flows'!$B$5:$B$33,J$4) | K12: =J12+SUMIFS('Investment Flows'!$C$5:$C$33,'Investment Flows'!$A$5:$A$33,$A12,'Investment Flows'!$B$5:$B$33,K$4) | L12: =K12+SUMIFS('Investment Flows'!$C$5:$C$33,'Investment Flows'!$A$5:$A$33,$A12,'Investment Flows'!$B$5:$B$33,L$4)
A13: Trading 212 Account | D13: 0 | E13: =D13+SUMIFS('Investment Flows'!$C$5:$C$33,'Investment Flows'!$A$5:$A$33,$A13,'Investment Flows'!$B$5:$B$33,E$4) | F13: =E13+SUMIFS('Investment Flows'!$C$5:$C$33,'Investment Flows'!$A$5:$A$33,$A13,'Investment Flows'!$B$5:$B$33,F$4) | G13: =F13+SUMIFS('Investment Flows'!$C$5:$C$33,'Investment Flows'!$A$5:$A$33,$A13,'Investment Flows'!$B$5:$B$33,G$4) | H13: =G13+SUMIFS('Investment Flows'!$C$5:$C$33,'Investment Flows'!$A$5:$A$33,$A13,'Investment Flows'!$B$5:$B$33,H$4) | I13: =H13+SUMIFS('Investment Flows'!$C$5:$C$33,'Investment Flows'!$A$5:$A$33,$A13,'Investment Flows'!$B$5:$B$33,I$4) | J13: =I13+SUMIFS('Investment Flows'!$C$5:$C$33,'Investment Flows'!$A$5:$A$33,$A13,'Investment Flows'!$B$5:$B$33,J$4) | K13: =J13+SUMIFS('Investment Flows'!$C$5:$C$33,'Investment Flows'!$A$5:$A$33,$A13,'Investment Flows'!$B$5:$B$33,K$4) | L13: =K13+SUMIFS('Investment Flows'!$C$5:$C$33,'Investment Flows'!$A$5:$A$33,$A13,'Investment Flows'!$B$5:$B$33,L$4)
A14: Portfolio | D14: =SUM(D6:D13) | E14: =SUM(E6:E13) | F14: =SUM(F6:F13) | G14: =SUM(G6:G13) | H14: =SUM(H6:H13) | I14: =SUM(I6:I13) | J14: =SUM(J6:J13) | K14: =SUM(K6:K13) | L14: =SUM(L6:L13)
A17: Cumulative return | E17: 2026-01 | F17: 2026-02 | G17: 2026-03 | H17: 2026-04 | I17: 2026-05 | J17: 2026-06 | K17: 2026-07 | L17: 2026-08
A18: Account | D18: 1 Jan | E18: Jan 2026 | F18: Feb 2026 | G18: Mar 2026 | H18: Apr 2026 | I18: May 2026 | J18: Jun 2026 | K18: Jul 2026 | L18: Aug 2026
A19: Certificados de Aforro CTT - Série E | D19: 0 | E19: =D19+SUMIFS('Investment Flows'!$D$5:$D$33,'Investment Flows'!$A$5:$A$33,$A19,'Investment Flows'!$B$5:$B$33,E$17) | F19: =E19+SUMIFS('Investment Flows'!$D$5:$D$33,'Investment Flows'!$A$5:$A$33,$A19,'Investment Flows'!$B$5:$B$33,F$17) | G19: =F19+SUMIFS('Investment Flows'!$D$5:$D$33,'Investment Flows'!$A$5:$A$33,$A19,'Investment Flows'!$B$5:$B$33,G$17) | H19: =G19+SUMIFS('Investment Flows'!$D$5:$D$33,'Investment Flows'!$A$5:$A$33,$A19,'Investment Flows'!$B$5:$B$33,H$17) | I19: =H19+SUMIFS('Investment Flows'!$D$5:$D$33,'Investment Flows'!$A$5:$A$33,$A19,'Investment Flows'!$B$5:$B$33,I$17) | J19: =I19+SUMIFS('Investment Flows'!$D$5:$D$33,'Investment Flows'!$A$5:$A$33,$A19,'Investment Flows'!$B$5:$B$33,J$17) | K19: =J19+SUMIFS('Investment Flows'!$D$5:$D$33,'Investment Flows'!$A$5:$A$33,$A19,'Investment Flows'!$B$5:$B$33,K$17) | L19: =K19+SUMIFS('Investment Flows'!$D$5:$D$33,'Investment Flows'!$A$5:$A$33,$A19,'Investment Flows'!$B$5:$B$33,L$17)
A20: Certificados de Aforro CTT - Série F | D20: 0 | E20: =D20+SUMIFS('Investment Flows'!$D$5:$D$33,'Investment Flows'!$A$5:$A$33,$A20,'Investment Flows'!$B$5:$B$33,E$17) | F20: =E20+SUMIFS('Investment Flows'!$D$5:$D$33,'Investment Flows'!$A$5:$A$33,$A20,'Investment Flows'!$B$5:$B$33,F$17) | G20: =F20+SUMIFS('Investment Flows'!$D$5:$D$33,'Investment Flows'!$A$5:$A$33,$A20,'Investment Flows'!$B$5:$B$33,G$17) | H20: =G20+SUMIFS('Investment Flows'!$D$5:$D$33,'Investment Flows'!$A$5:$A$33,$A20,'Investment Flows'!$B$5:$B$33,H$17) | I20: =H20+SUMIFS('Investment Flows'!$D$5:$D$33,'Investment Flows'!$A$5:$A$33,$A20,'Investment Flows'!$B$5:$B$33,I$17) | J20: =I20+SUMIFS('Investment Flows'!$D$5:$D$33,'Investment Flows'!$A$5:$A$33,$A20,'Investment Flows'!$B$5:$B$33,J$17) | K20: =J20+SUMIFS('Investment Flows'!$D$5:$D$33,'Investment Flows'!$A$5:$A$33,$A20,'Investment Flows'!$B$5:$B$33,K$17) | L20: =K20+SUMIFS('Investment Flows'!$D$5:$D$33,'Investment Flows'!$A$5:$A$33,$A20,'Investment Flows'!$B$5:$B$33,L$17)
A21: Revolut - Fundo Emergência | D21: 0 | E21: =D21+SUMIFS('Investment Flows'!$D$5:$D$33,'Investment Flows'!$A$5:$A$33,$A21,'Investment Flows'!$B$5:$B$33,E$17) | F21: =E21+SUMIFS('Investment Flows'!$D$5:$D$33,'Investment Flows'!$A$5:$A$33,$A21,'Investment Flows'!$B$5:$B$33,F$17) | G21: =F21+SUMIFS('Investment Flows'!$D$5:$D$33,'Investment Flows'!$A$5:$A$33,$A21,'Investment Flows'!$B$5:$B$33,G$17) | H21: =G21+SUMIFS('Investment Flows'!$D$5:$D$33,'Investment Flows'!$A$5:$A$33,$A21,'Investment Flows'!$B$5:$B$33,H$17) | I21: =H21+SUMIFS('Investment Flows'!$D$5:$D$33,'Investment Flows'!$A$5:$A$33,$A21,'Investment Flows'!$B$5:$B$33,I$17) | J21: =I21+SUMIFS('Investment Flows'!$D$5:$D$33,'Investment Flows'!$A$5:$A$33,$A21,'Investment Flows'!$B$5:$B$33,J$17) | K21: =J21+SUMIFS('Investment Flows'!$D$5:$D$33,'Investment Flows'!$A$5:$A$33,$A21,'Investment Flows'!$B$5:$B$33,K$17) | L21: =K21+SUMIFS('Investment Flows'!$D$5:$D$33,'Investment Flows'!$A$5:$A$33,$A21,'Investment Flows'!$B$5:$B$33,L$17)
A22: Revolut - Wealth Build | D22: 0 | E22: =D22+SUMIFS('Investment Flows'!$D$5:$D$33,'Investment Flows'!$A$5:$A$33,$A22,'Investment Flows'!$B$5:$B$33,E$17) | F22: =E22+SUMIFS('Investment Flows'!$D$5:$D$33,'Investment Flows'!$A$5:$A$33,$A22,'Investment Flows'!$B$5:$B$33,F$17) | G22: =F22+SUMIFS('Investment Flows'!$D$5:$D$33,'Investment Flows'!$A$5:$A$33,$A22,'Investment Flows'!$B$5:$B$33,G$17) | H22: =G22+SUMIFS('Investment Flows'!$D$5:$D$33,'Investment Flows'!$A$5:$A$33,$A22,'Investment Flows'!$B$5:$B$33,H$17) | I22: =H22+SUMIFS('Investment Flows'!$D$5:$D$33,'Investment Flows'!$A$5:$A$33,$A22,'Investment Flows'!$B$5:$B$33,I$17) | J22: =I22+SUMIFS('Investment Flows'!$D$5:$D$33,'Investment Flows'!$A$5:$A$33,$A22,'Investment Flows'!$B$5:$B$33,J$17) | K22: =J22+SUMIFS('Investment Flows'!$D$5:$D$33,'Investment Flows'!$A$5:$A$33,$A22,'Investment Flows'!$B$5:$B$33,K$17) | L22: =K22+SUMIFS('Investment Flows'!$D$5:$D$33,'Investment Flows'!$A$5:$A$33,$A22,'Investment Flows'!$B$5:$B$33,L$17)
A23: Robinhood | D23: 0 | E23: =D23+SUMIFS('Investment Flows'!$D$5:$D$33,'Investment Flows'!$A$5:$A$33,$A23,'Investment Flows'!$B$5:$B$33,E$17) | F23: =E23+SUMIFS('Investment Flows'!$D$5:$D$33,'Investment Flows'!$A$5:$A$33,$A23,'Investment Flows'!$B$5:$B$33,F$17) | G23: =F23+SUMIFS('Investment Flows'!$D$5:$D$33,'Investment Flows'!$A$5:$A$33,$A23,'Investment Flows'!$B$5:$B$33,G$17) | H23: =G23+SUMIFS('Investment Flows'!$D$5:$D$33,'Investment Flows'!$A$5:$A$33,$A23,'Investment Flows'!$B$5:$B$33,H$17) | I23: =H23+SUMIFS('Investment Flows'!$D$5:$D$33,'Investment Flows'!$A$5:$A$33,$A23,'Investment Flows'!$B$5:$B$33,I$17) | J23: =I23+SUMIFS('Investment Flows'!$D$5:$D$33,'Investment Flows'!$A$5:$A$33,$A23,'Investment Flows'!$B$5:$B$33,J$17) | K23: =J23+SUMIFS('Investment Flows'!$D$5:$D$33,'Investment Flows'!$A$5:$A$33,$A23,'Investment Flows'!$B$5:$B$33,K$17) | L23: =K23+SUMIFS('Investment Flows'!$D$5:$D$33,'Investment Flows'!$A$5:$A$33,$A23,'Investment Flows'!$B$5:$B$33,L$17)
A24: Trade Republic Inv. - Brokerage | D24: 0 | E24: =D24+SUMIFS('Investment Flows'!$D$5:$D$33,'Investment Flows'!$A$5:$A$33,$A24,'Investment Flows'!$B$5:$B$33,E$17) | F24: =E24+SUMIFS('Investment Flows'!$D$5:$D$33,'Investment Flows'!$A$5:$A$33,$A24,'Investment Flows'!$B$5:$B$33,F$17) | G24: =F24+SUMIFS('Investment Flows'!$D$5:$D$33,'Investment Flows'!$A$5:$A$33,$A24,'Investment Flows'!$B$5:$B$33,G$17) | H24: =G24+SUMIFS('Investment Flows'!$D$5:$D$33,'Investment Flows'!$A$5:$A$33,$A24,'Investment Flows'!$B$5:$B$33,H$17) | I24: =H24+SUMIFS('Investment Flows'!$D$5:$D$33,'Investment Flows'!$A$5:$A$33,$A24,'Investment Flows'!$B$5:$B$33,I$17) | J24: =I24+SUMIFS('Investment Flows'!$D$5:$D$33,'Investment Flows'!$A$5:$A$33,$A24,'Investment Flows'!$B$5:$B$33,J$17) | K24: =J24+SUMIFS('Investment Flows'!$D$5:$D$33,'Investment Flows'!$A$5:$A$33,$A24,'Investment Flows'!$B$5:$B$33,K$17) | L24: =K24+SUMIFS('Investment Flows'!$D$5:$D$33,'Investment Flows'!$A$5:$A$33,$A24,'Investment Flows'!$B$5:$B$33,L$17)
A25: Trade Republic Inv. - Crypto | D25: 0 | E25: =D25+SUMIFS('Investment Flows'!$D$5:$D$33,'Investment Flows'!$A$5:$A$33,$A25,'Investment Flows'!$B$5:$B$33,E$17) | F25: =E25+SUMIFS('Investment Flows'!$D$5:$D$33,'Investment Flows'!$A$5:$A$33,$A25,'Investment Flows'!$B$5:$B$33,F$17) | G25: =F25+SUMIFS('Investment Flows'!$D$5:$D$33,'Investment Flows'!$A$5:$A$33,$A25,'Investment Flows'!$B$5:$B$33,G$17) | H25: =G25+SUMIFS('Investment Flows'!$D$5:$D$33,'Investment Flows'!$A$5:$A$33,$A25,'Investment Flows'!$B$5:$B$33,H$17) | I25: =H25+SUMIFS('Investment Flows'!$D$5:$D$33,'Investment Flows'!$A$5:$A$33,$A25,'Investment Flows'!$B$5:$B$33,I$17) | J25: =I25+SUMIFS('Investment Flows'!$D$5:$D$33,'Investment Flows'!$A$5:$A$33,$A25,'Investment Flows'!$B$5:$B$33,J$17) | K25: =J25+SUMIFS('Investment Flows'!$D$5:$D$33,'Investment Flows'!$A$5:$A$33,$A25,'Investment Flows'!$B$5:$B$33,K$17) | L25: =K25+SUMIFS('Investment Flows'!$D$5:$D$33,'Investment Flows'!$A$5:$A$33,$A25,'Investment Flows'!$B$5:$B$33,L$17)
A26: Trading 212 Account | D26: 0 | E26: =D26+SUMIFS('Investment Flows'!$D$5:$D$33,'Investment Flows'!$A$5:$A$33,$A26,'Investment Flows'!$B$5:$B$33,E$17) | F26: =E26+SUMIFS('Investment Flows'!$D$5:$D$33,'Investment Flows'!$A$5:$A$33,$A26,'Investment Flows'!$B$5:$B$33,F$17) | G26: =F26+SUMIFS('Investment Flows'!$D$5:$D$33,'Investment Flows'!$A$5:$A$33,$A26,'Investment Flows'!$B$5:$B$33,G$17) | H26: =G26+SUMIFS('Investment Flows'!$D$5:$D$33,'Investment Flows'!$A$5:$A$33,$A26,'Investment Flows'!$B$5:$B$33,H$17) | I26: =H26+SUMIFS('Investment Flows'!$D$5:$D$33,'Investment Flows'!$A$5:$A$33,$A26,'Investment Flows'!$B$5:$B$33,I$17) | J26: =I26+SUMIFS('Investment Flows'!$D$5:$D$33,'Investment Flows'!$A$5:$A$33,$A26,'Investment Flows'!$B$5:$B$33,J$17) | K26: =J26+SUMIFS('Investment Flows'!$D$5:$D$33,'Investment Flows'!$A$5:$A$33,$A26,'Investment Flows'!$B$5:$B$33,K$17) | L26: =K26+SUMIFS('Investment Flows'!$D$5:$D$33,'Investment Flows'!$A$5:$A$33,$A26,'Investment Flows'!$B$5:$B$33,L$17)
A27: Portfolio | D27: =SUM(D19:D26) | E27: =SUM(E19:E26) | F27: =SUM(F19:F26) | G27: =SUM(G19:G26) | H27: =SUM(H19:H26) | I27: =SUM(I19:I26) | J27: =SUM(J19:J26) | K27: =SUM(K19:K26) | L27: =SUM(L19:L26)
A30: Portfolio value | E30: 2026-01 | F30: 2026-02 | G30: 2026-03 | H30: 2026-04 | I30: 2026-05 | J30: 2026-06 | K30: 2026-07 | L30: 2026-08
A31: Account | D31: 1 Jan | E31: Jan 2026 | F31: Feb 2026 | G31: Mar 2026 | H31: Apr 2026 | I31: May 2026 | J31: Jun 2026 | K31: Jul 2026 | L31: Aug 2026
A32: Certificados de Aforro CTT - Série E | D32: =D6+D19 | E32: =E6+E19 | F32: =F6+F19 | G32: =G6+G19 | H32: =H6+H19 | I32: =I6+I19 | J32: =J6+J19 | K32: =K6+K19 | L32: =L6+L19
A33: Certificados de Aforro CTT - Série F | D33: =D7+D20 | E33: =E7+E20 | F33: =F7+F20 | G33: =G7+G20 | H33: =H7+H20 | I33: =I7+I20 | J33: =J7+J20 | K33: =K7+K20 | L33: =L7+L20
A34: Revolut - Fundo Emergência | D34: =D8+D21 | E34: =E8+E21 | F34: =F8+F21 | G34: =G8+G21 | H34: =H8+H21 | I34: =I8+I21 | J34: =J8+J21 | K34: =K8+K21 | L34: =L8+L21
A35: Revolut - Wealth Build | D35: =D9+D22 | E35: =E9+E22 | F35: =F9+F22 | G35: =G9+G22 | H35: =H9+H22 | I35: =I9+I22 | J35: =J9+J22 | K35: =K9+K22 | L35: =L9+L22
A36: Robinhood | D36: =D10+D23 | E36: =E10+E23 | F36: =F10+F23 | G36: =G10+G23 | H36: =H10+H23 | I36: =I10+I23 | J36: =J10+J23 | K36: =K10+K23 | L36: =L10+L23
A37: Trade Republic Inv. - Brokerage | D37: =D11+D24 | E37: =E11+E24 | F37: =F11+F24 | G37: =G11+G24 | H37: =H11+H24 | I37: =I11+I24 | J37: =J11+J24 | K37: =K11+K24 | L37: =L11+L24
A38: Trade Republic Inv. - Crypto | D38: =D12+D25 | E38: =E12+E25 | F38: =F12+F25 | G38: =G12+G25 | H38: =H12+H25 | I38: =I12+I25 | J38: =J12+J25 | K38: =K12+K25 | L38: =L12+L25
A39: Trading 212 Account | D39: =D13+D26 | E39: =E13+E26 | F39: =F13+F26 | G39: =G13+G26 | H39: =H13+H26 | I39: =I13+I26 | J39: =J13+J26 | K39: =K13+K26 | L39: =L13+L26
A40: Portfolio | D40: =SUM(D32:D39) | E40: =SUM(E32:E39) | F40: =SUM(F32:F39) | G40: =SUM(G32:G39) | H40: =SUM(H32:H39) | I40: =SUM(I32:I39) | J40: =SUM(J32:J39) | K40: =SUM(K32:K39) | L40: =SUM(L32:L39)
A43: Summary at 5 Aug 2026
A44: Capital invested | E44: =L14
A45: Portfolio value | E45: =L40
A46: Return earned | E46: =L27
A47: Return on capital | E47: =L27/L14
...

Sheet Charts
A1: Charts
A2: Both charts read straight from the Balances sheet. In the per-account chart, right-click → Select Data to hide accounts you don't want on screen.
